<mujoco model='h1-hammer'>

    <!-- default -->
    <default>
        <default class="board">
            <geom type="box" material="MatWood" />
            <general
                user="0 1 0.03 0.0939711 0.513477 0.0358776 1.23598 8.40409 0.485031 6.04244 1.02187 0.175297 0.121642 0 0 0" />
        </default>
    </default>

    <!-- ======= CONTACTS ======= -->
    <contact>
        <exclude body1='nail_board' body2='nail_body' />
    </contact>

    <!-- ======= SENSORS ======= -->
    <sensor>
        <touch site="S_target" name="S_nail" />
    </sensor>

    <!-- asset -->
    <asset>
        <!-- <texture type="cube" name="texgeom" builtin="flat" mark="cross" rgb1="0.3 0.6 0.5"
        rgb2="0.3 0.6 0.5" width="127" height="762" /> -->
        <texture type="cube" name="wood" file="./resources/wood.png" />
        <!-- <texture type="2d" name="wood2d" file="wood.png" /> -->
        <!-- <texture type="cube" name="square" file="square.png" /> -->
        <texture type="cube" name="foil" file="./resources/silverRaw.png" />
        <!-- <texture type="cube" name="woodb" file="woodb.png" /> -->
        <texture type="2d" name="groundplane" builtin="checker" rgb1="0.2 0.3 0.4"
            rgb2="0.1 0.2 0.3" width="100" height="100" />
        <!-- <texture type="2d" name="marble2d" file="marble.png" /> -->
        <texture type="cube" name="marblecube" file="./resources/marble.png" />
        <!-- <material name="MatColl" specular="1" shininess="0.3" reflectance="0.5" rgba="0.4 0.5
        0.6 1" />
        <material name="MatViz" specular="0.75" shininess="0.1" reflectance="0.5" rgba="0.9 0.7 0.5 1" />
        <material name="MatGnd" specular="0.3" shininess="0.3" reflectance="0.3" rgba="0.5 0.55 0.5 1" /> -->
        <!-- <material name="object" texture="texgeom" /> -->
        <material name="groundplane" texture="groundplane" texrepeat="10 10" />
        <!-- <material name="table2d" texture="marble2d" reflectance="0.3" rgba="0.8 0.8 0.8 1" /> -->
        <material name="tablecube" texture="marblecube" rgba="0.8 0.8 0.8 1" />
        <material name="MatFoil" texture="foil" specular="1" shininess="0.3" rgba="0.9 0.9 0.9 1" />
        <!-- <material name="MatPlane" specular="0.3" shininess="0.3" rgba="0.3 0.3 0.2 1" /> -->
        <material name="MatWood" texture="wood" texrepeat="3 3" specular="0.4" shininess="0.1" />
        <!-- <material name="MatSquare" texture="square" specular="1" shininess="0.6" rgba="0.8 0.8
        0.8 1" /> -->
        <!-- <material name="MatWoodR" texture="wood" specular="1" shininess="0.3" rgba="1 0.5 0.5
        1" />
        <material name="MatWoodG" texture="wood" specular="1" shininess="0.3" rgba="0.2 1 0.2 1" />
        <material name="MatWoodB" texture="woodb" specular="1" shininess="0.3" /> -->
        <!-- <mesh name="forearm_simple" file="forearm_simple.stl" scale="1 1 1"/>
        <mesh name="wrist" file="wrist.stl" />
        <mesh name="palm" file="palm.stl" />
        <mesh name="lfmetacarpal" file="lfmetacarpal.stl" />
        <mesh name="knuckle" file="knuckle.stl" />
        <mesh name="F3" file="F3.stl" />
        <mesh name="F2" file="F2.stl" />
        <mesh name="F1" file="F1.stl" />
        <mesh name="TH3_z" file="TH3_z.stl" />
        <mesh name="TH2_z" file="TH2_z.stl" />
        <mesh name="TH1_z" file="TH1_z.stl" /> -->
    </asset>

    <!-- ======= WORLD ======= -->
    <worldbody>
        <light directional='false' diffuse='.7 .7 .7' specular='0.03 0.03 0.03' pos='-1 -1.0 4.0'
            dir='1 1.0 -4' />
        <geom name='ground' size="1.5 1.5 0.25" pos="0 0 -1" type="plane" contype="1"
            conaffinity="0" material="groundplane" />
        <camera name="fixed" pos="0 -0.7 0.7" quat="0.92388 0.382683 0 0" />
        <!-- Camera for the VIL paper -->
        <camera name="vil_camera" pos="0 -1.2 1.2" quat="0.92388 0.382683 0 0" />

        <!-- ======= TABLE ======= -->
        <body name="table">
            <!-- <geom size="0.5 0.5 0.025" type="plane" material="table2d" /> --> <!-- Plane has better contacts -->
            <geom size="0.45 0.45 0.025" pos="0 0 -0.025" type="box" material="tablecube" />
            <geom size="0.04 0.5" pos="0.4 0.4 -0.501" quat="0 1 0 0" type="cylinder" contype="0"
                conaffinity="0" />
            <geom size="0.04 0.5" pos="-0.4 0.4 -0.501" quat="0 1 0 0" type="cylinder" contype="0"
                conaffinity="0" />
            <geom size="0.04 0.5" pos="0.4 -0.4 -0.501" quat="0 1 0 0" type="cylinder" contype="0"
                conaffinity="0" />
            <geom size="0.04 0.5" pos="-0.4 -0.4 -0.501" quat="0 1 0 0" type="cylinder" contype="0"
                conaffinity="0" />
        </body>

        <!-- ======= Nail ======= -->
        <!-- quat: 0.583833 0.583368 -0.399421 -0.399104 -->
        <body name="nail_board" pos="0.05 0 0.185245" quat="1 0 0 0"
            user="1001 0 2002 0.05 0 0.1 0.05 0 0.25">
            <inertial pos="0 0 0" mass="0.512" diaginertia="0.00110933 0.00110933 0.00218453" />
            <geom name="board" class="board" size="0.08 0.08 0.01" />
            <site name="nail_goal" pos="0 0 0.01" size="0.034 0.005" type="cylinder"
                material="MatWood" rgba="1 0.8 0.8 1" />
            <body name="nail_head" pos="0 0 0">
                <inertial pos="0 0 0.0775281" mass="0.0699004"
                    diaginertia="8.23129e-05 8.23129e-05 2.51426e-05" />
                <joint name="nail_rot_x" pos="0 0 0" axis="1 0 0" type="hinge" frictionloss="50" />
                <joint name="nail_rot_y" pos="0 0 0" axis="0 1 0" type="hinge" frictionloss="50" />
                <joint name="nail_dir_z" pos="0 0 0" axis="0 0 -1" type="slide" damping="10"
                    frictionloss="50" />
                <joint name="nail_dir_x" pos="0 0 0" axis="1 0 0" type="slide" damping="10"
                    frictionloss="50" />
                <joint name="nail_dir_y" pos="0 0 0" axis="0 1 0" type="slide" damping="10"
                    frictionloss="50" />
                <geom size="0.035 0.005" pos="0 0 0.1" type="cylinder" material="MatFoil" />
                <site name="S_target" pos="0 0 0.101" size="0.034 0.005" type="cylinder"
                    rgba="0 1 0 0.2" />
                <body name="nail_body" pos="0 0 0">
                    <geom size="0.01 0.05" pos="0 0 0.05" type="cylinder" material="MatFoil" />
                </body>
            </body>
        </body>

        <!-- ======= Hammer ======= -->
        <body name="Object" pos="0 -0.2 0.035" quat="0.707388 0.706825 0 0">
            <inertial pos="-0.11025 0 0" quat="0.50001 0.49999 0.49999 0.50001" mass="0.253442"
                diaginertia="0.00349644 0.00345287 8.947e-05" />
            <joint name="OBJTx" pos="0 0 0" axis="1 0 0" type="slide" limited="false" damping="0" />
            <joint name="OBJTy" pos="0 0 0" axis="0 1 0" type="slide" limited="false" damping="0" />
            <joint name="OBJTz" pos="0 0 0" axis="0 0 1" type="slide" limited="false" damping="0" />
            <joint name="OBJRx" pos="0 0 0" axis="1 0 0" limited="false" damping="0.1" />
            <joint name="OBJRy" pos="0 0 0" axis="0 1 0" limited="false" damping="0.1" />
            <joint name="OBJRz" pos="0 0 0" axis="0 0 1" limited="false" damping="0.1" />
            <geom name="handle" size="0.025 0.05" quat="0.707388 0 0.706825 0" type="capsule"
                condim="4" material="MatWood" />
            <geom name="neck" size="0.007 0.085" pos="-0.14 0 0" quat="0.707388 0 0.706825 0"
                type="capsule" condim="4" rgba="1 1 1 1" />
            <geom name="head" size="0.02 0.04" pos="-0.24 0 0" type="cylinder" condim="4"
                rgba="0.4 0.4 0.4 1" />
            <site name="tool" pos="-0.2 0 -0.04" size="0.01" group="4" rgba="0.4 0.8 0.4 1" />
        </body>

    </worldbody>


    <actuator>

    </actuator>

    <sensor>

    </sensor>

</mujoco>